<?xml version="1.0" encoding="utf-8"?>
<!-- =================================================================================== -->
<!-- |    This document was autogenerated by xacro from robot.xacro                    | -->
<!-- |    EDITING THIS FILE BY HAND IS NOT RECOMMENDED                                 | -->
<!-- =================================================================================== -->
<robot name="a1">
  <!-- dynamics inertial value -->
  <!-- trunk -->
  <!-- <xacro:property name="trunk_mass" value="5.660"/>
    <xacro:property name="trunk_com_x" value="0.012731"/>
    <xacro:property name="trunk_com_y" value="0.002186"/>
    <xacro:property name="trunk_com_z" value="0.000515"/>
    <xacro:property name="trunk_ixx" value="0.016839930"/>
    <xacro:property name="trunk_ixy" value="0.000083902"/>
    <xacro:property name="trunk_ixz" value="0.000597679"/>
    <xacro:property name="trunk_iyy" value="0.056579028"/>
    <xacro:property name="trunk_iyz" value="0.000025134"/>
    <xacro:property name="trunk_izz" value="0.064713601"/> -->
  <material name="black">
    <color rgba="0.0 0.0 0.0 1.0"/>
  </material>
  <material name="blue">
    <color rgba="0.0 0.0 0.8 1.0"/>
  </material>
  <material name="green">
    <color rgba="0.0 0.8 0.0 1.0"/>
  </material>
  <material name="grey">
    <color rgba="0.2 0.2 0.2 1.0"/>
  </material>
  <material name="silver">
    <color rgba="0.913725490196 0.913725490196 0.847058823529 1.0"/>
  </material>
  <material name="orange">
    <color rgba="1.0 0.423529411765 0.0392156862745 1.0"/>
  </material>
  <material name="brown">
    <color rgba="0.870588235294 0.811764705882 0.764705882353 1.0"/>
  </material>
  <material name="red">
    <color rgba="0.8 0.0 0.0 1.0"/>
  </material>
  <material name="white">
    <color rgba="1.0 1.0 1.0 1.0"/>
  </material>
  <link name="base_link">
    <visual>
      <origin rpy="0 0 0" xyz="0 0 0"/>
      <geometry>
        <mesh filename="package://meshes/trunk.dae" scale="1 1 1"/>
      </geometry>
      <material name="orange"/>
    </visual>
    <collision>
      <origin rpy="0 0 0" xyz="0 0 0"/>
      <geometry>
        <box size="0.267 0.194 0.114"/>
      </geometry>
    </collision>
    <inertial>
      <origin rpy="0 0 0" xyz="0.0 0.0041 -0.0005"/>
      <mass value="6.0"/>
      <inertia ixx="0.0158533" ixy="-3.66e-05" ixz="-6.11e-05" iyy="0.0377999" iyz="-2.75e-05" izz="0.0456542"/>
    </inertial>
  </link>


  <joint name="FL_HAA" type="revolute">
    <origin rpy="0 0 0" xyz="0.1805 0.047 0"/>
    <parent link="base_link"/>
    <child link="FL_SHOULDER"/>
    <axis xyz="1 0 0"/>
    <dynamics damping="0.01" friction="0.2"/>
    <limit effort="33.5" lower="-0.802851455917" upper="0.802851455917" velocity="21"/>
  </joint>
  <link name="FL_SHOULDER">
    <visual>
      <origin rpy="0 0 0" xyz="0 0 0"/>
      <geometry>
        <mesh filename="package://meshes/hip.dae" scale="1 1 1"/>
      </geometry>
      <material name="orange"/>
    </visual>
    <collision>
      <origin rpy="1.57079632679 0 0" xyz="0 0 0"/>
      <geometry>
        <cylinder length="0.04" radius="0.046"/>
      </geometry>
    </collision>
    <inertial>
      <origin rpy="0 0 0" xyz="-0.003311 0.000635 3.1e-05"/>
      <mass value="0.696"/>
      <inertia ixx="0.000469246" ixy="-9.409e-06" ixz="-3.42e-07" iyy="0.00080749" iyz="-4.66e-07" izz="0.000552929"/>
    </inertial>
  </link>
  <joint name="FL_HIP_FIXED" type="fixed">
    <origin rpy="0 0 0" xyz="0 0.081 0"/>
    <parent link="FL_SHOULDER"/>
    <child link="FL_THIGH_COLLISION"/>
  </joint>
  <!-- this link is only for collision -->
  <link name="FL_THIGH_COLLISION">
    <collision>
      <origin rpy="1.57079632679 0 0" xyz="0 0 0"/>
      <geometry>
        <cylinder length="0.032" radius="0.041"/>
      </geometry>
    </collision>
  </link>
  <joint name="FL_HFE" type="revolute">
    <origin rpy="0 0 0" xyz="0 0.0838 0"/>
    <parent link="FL_SHOULDER"/>
    <child link="FL_UPPER_LEG"/>
    <axis xyz="0 1 0"/>
    <dynamics damping="0.01" friction="0.2"/>
    <limit effort="33.5" lower="-1.0471975512" upper="4.18879020479" velocity="21"/>
  </joint>
  <link name="FL_UPPER_LEG">
    <visual>
      <origin rpy="0 0 0" xyz="0 0 0"/>
      <geometry>
        <mesh filename="package://meshes/thigh.dae" scale="1 1 1"/>
      </geometry>
      <material name="orange"/>
    </visual>
    <collision>
      <origin rpy="0 1.57079632679 0" xyz="0 0 -0.1"/>
      <geometry>
        <box size="0.2 0.0245 0.034"/>
      </geometry>
    </collision>
    <inertial>
      <origin rpy="0 0 0" xyz="-0.003237 -0.022327 -0.027326"/>
      <mass value="1.013"/>
      <inertia ixx="0.005529065" ixy="4.825e-06" ixz="0.000343869" iyy="0.005139339" iyz="2.2448e-05" izz="0.001367788"/>
    </inertial>
  </link>
  <joint name="FL_KFE" type="revolute">
    <origin rpy="0 0 0" xyz="0 0 -0.2"/>
    <parent link="FL_UPPER_LEG"/>
    <child link="FL_LOWER_LEG"/>
    <axis xyz="0 1 0"/>
    <dynamics damping="0.01" friction="0.2"/>
    <limit effort="33.5" lower="-2.69653369433" upper="-0.916297857297" velocity="21"/>
  </joint>
  <link name="FL_LOWER_LEG">
    <visual>
      <origin rpy="0 0 0" xyz="0 0 0"/>
      <geometry>
        <mesh filename="package://meshes/calf.dae" scale="1 1 1"/>
      </geometry>
      <material name="orange"/>
    </visual>
    <collision>
      <origin rpy="0 1.57079632679 0" xyz="0 0 -0.1"/>
      <geometry>
        <box size="0.2 0.016 0.016"/>
      </geometry>
    </collision>
    <inertial>
      <origin rpy="0 0 0" xyz="0.006435 0.0 -0.107388"/>
      <mass value="0.166"/>
      <inertia ixx="0.002997972" ixy="0.0" ixz="-0.000141163" iyy="0.003014022" iyz="0.0" izz="3.2426e-05"/>
    </inertial>
  </link>
  <joint name="FL_ANKLE" type="fixed">
    <origin rpy="0 0 0" xyz="0 0 -0.2"/>
    <parent link="FL_LOWER_LEG"/>
    <child link="FL_FOOT"/>
  </joint>
  <link name="FL_FOOT">
    <visual>
      <origin rpy="0 0 0" xyz="0 0 0"/>
      <geometry>
        <sphere radius="0.01"/>
      </geometry>
      <material name="orange"/>
    </visual>
    <collision>
      <origin rpy="0 0 0" xyz="0 0 0"/>
      <geometry>
        <sphere radius="0.02"/>
      </geometry>
    </collision>
    <inertial>
      <mass value="0.06"/>
      <inertia ixx="9.6e-06" ixy="0.0" ixz="0.0" iyy="9.6e-06" iyz="0.0" izz="9.6e-06"/>
    </inertial>
  </link>

  <joint name="FR_HAA" type="revolute">
    <origin rpy="0 0 0" xyz="0.1805 -0.047 0"/>
    <parent link="base_link"/>
    <child link="FR_SHOULDER"/>
    <axis xyz="1 0 0"/>
    <dynamics damping="0.01" friction="0.2"/>
    <limit effort="33.5" lower="-0.802851455917" upper="0.802851455917" velocity="21"/>
  </joint>
  <link name="FR_SHOULDER">
    <visual>
      <origin rpy="3.14159265359 0 0" xyz="0 0 0"/>
      <geometry>
        <mesh filename="package://meshes/hip.dae" scale="1 1 1"/>
      </geometry>
      <material name="orange"/>
    </visual>
    <collision>
      <origin rpy="1.57079632679 0 0" xyz="0 0 0"/>
      <geometry>
        <cylinder length="0.04" radius="0.046"/>
      </geometry>
    </collision>
    <inertial>
      <origin rpy="0 0 0" xyz="-0.003311 -0.000635 3.1e-05"/>
      <mass value="0.696"/>
      <inertia ixx="0.000469246" ixy="9.409e-06" ixz="-3.42e-07" iyy="0.00080749" iyz="4.66e-07" izz="0.000552929"/>
    </inertial>
  </link>
  <joint name="FR_HIP_FIXED" type="fixed">
    <origin rpy="0 0 0" xyz="0 -0.081 0"/>
    <parent link="FR_SHOULDER"/>
    <child link="FR_THIGH_COLLISION"/>
  </joint>
  <!-- this link is only for collision -->
  <link name="FR_THIGH_COLLISION">
    <collision>
      <origin rpy="1.57079632679 0 0" xyz="0 0 0"/>
      <geometry>
        <cylinder length="0.032" radius="0.041"/>
      </geometry>
    </collision>
  </link>
  <joint name="FR_HFE" type="revolute">
    <origin rpy="0 0 0" xyz="0 -0.0838 0"/>
    <parent link="FR_SHOULDER"/>
    <child link="FR_UPPER_LEG"/>
    <axis xyz="0 1 0"/>
    <dynamics damping="0.01" friction="0.2"/>
    <limit effort="33.5" lower="-1.0471975512" upper="4.18879020479" velocity="21"/>
  </joint>
  <link name="FR_UPPER_LEG">
    <visual>
      <origin rpy="0 0 0" xyz="0 0 0"/>
      <geometry>
        <mesh filename="package://meshes/thigh_mirror.dae" scale="1 1 1"/>
      </geometry>
      <material name="orange"/>
    </visual>
    <collision>
      <origin rpy="0 1.57079632679 0" xyz="0 0 -0.1"/>
      <geometry>
        <box size="0.2 0.0245 0.034"/>
      </geometry>
    </collision>
    <inertial>
      <origin rpy="0 0 0" xyz="-0.003237 0.022327 -0.027326"/>
      <mass value="1.013"/>
      <inertia ixx="0.005529065" ixy="-4.825e-06" ixz="0.000343869" iyy="0.005139339" iyz="-2.2448e-05" izz="0.001367788"/>
    </inertial>
  </link>
  <joint name="FR_KFE" type="revolute">
    <origin rpy="0 0 0" xyz="0 0 -0.2"/>
    <parent link="FR_UPPER_LEG"/>
    <child link="FR_LOWER_LEG"/>
    <axis xyz="0 1 0"/>
    <dynamics damping="0.01" friction="0.2"/>
    <limit effort="33.5" lower="-2.69653369433" upper="-0.916297857297" velocity="21"/>
  </joint>
  <link name="FR_LOWER_LEG">
    <visual>
      <origin rpy="0 0 0" xyz="0 0 0"/>
      <geometry>
        <mesh filename="package://meshes/calf.dae" scale="1 1 1"/>
      </geometry>
      <material name="orange"/>
    </visual>
    <collision>
      <origin rpy="0 1.57079632679 0" xyz="0 0 -0.1"/>
      <geometry>
        <box size="0.2 0.016 0.016"/>
      </geometry>
    </collision>
    <inertial>
      <origin rpy="0 0 0" xyz="0.006435 0.0 -0.107388"/>
      <mass value="0.166"/>
      <inertia ixx="0.002997972" ixy="0.0" ixz="-0.000141163" iyy="0.003014022" iyz="0.0" izz="3.2426e-05"/>
    </inertial>
  </link>
  <joint name="FR_ANKLE" type="fixed">
    <origin rpy="0 0 0" xyz="0 0 -0.2"/>
    <parent link="FR_LOWER_LEG"/>
    <child link="FR_FOOT"/>
  </joint>
  <link name="FR_FOOT">
    <visual>
      <origin rpy="0 0 0" xyz="0 0 0"/>
      <geometry>
        <sphere radius="0.01"/>
      </geometry>
      <material name="orange"/>
    </visual>
    <collision>
      <origin rpy="0 0 0" xyz="0 0 0"/>
      <geometry>
        <sphere radius="0.02"/>
      </geometry>
    </collision>
    <inertial>
      <mass value="0.06"/>
      <inertia ixx="9.6e-06" ixy="0.0" ixz="0.0" iyy="9.6e-06" iyz="0.0" izz="9.6e-06"/>
    </inertial>
  </link>

  <joint name="HL_HAA" type="revolute">
    <origin rpy="0 0 0" xyz="-0.1805 0.047 0"/>
    <parent link="base_link"/>
    <child link="HL_SHOULDER"/>
    <axis xyz="1 0 0"/>
    <dynamics damping="0.01" friction="0.2"/>
    <limit effort="33.5" lower="-0.802851455917" upper="0.802851455917" velocity="21"/>
  </joint>
  <link name="HL_SHOULDER">
    <visual>
      <origin rpy="0 3.14159265359 0" xyz="0 0 0"/>
      <geometry>
        <mesh filename="package://meshes/hip.dae" scale="1 1 1"/>
      </geometry>
      <material name="orange"/>
    </visual>
    <collision>
      <origin rpy="1.57079632679 0 0" xyz="0 0 0"/>
      <geometry>
        <cylinder length="0.04" radius="0.046"/>
      </geometry>
    </collision>
    <inertial>
      <origin rpy="0 0 0" xyz="0.003311 0.000635 3.1e-05"/>
      <mass value="0.696"/>
      <inertia ixx="0.000469246" ixy="9.409e-06" ixz="3.42e-07" iyy="0.00080749" iyz="-4.66e-07" izz="0.000552929"/>
    </inertial>
  </link>
  <joint name="HL_HIP_FIXED" type="fixed">
    <origin rpy="0 0 0" xyz="0 0.081 0"/>
    <parent link="HL_SHOULDER"/>
    <child link="HL_THIGH_COLLISION"/>
  </joint>
  <!-- this link is only for collision -->
  <link name="HL_THIGH_COLLISION">
    <collision>
      <origin rpy="1.57079632679 0 0" xyz="0 0 0"/>
      <geometry>
        <cylinder length="0.032" radius="0.041"/>
      </geometry>
    </collision>
  </link>
  <joint name="HL_HFE" type="revolute">
    <origin rpy="0 0 0" xyz="0 0.0838 0"/>
    <parent link="HL_SHOULDER"/>
    <child link="HL_UPPER_LEG"/>
    <axis xyz="0 1 0"/>
    <dynamics damping="0.01" friction="0.2"/>
    <limit effort="33.5" lower="-1.0471975512" upper="4.18879020479" velocity="21"/>
  </joint>
  <link name="HL_UPPER_LEG">
    <visual>
      <origin rpy="0 0 0" xyz="0 0 0"/>
      <geometry>
        <mesh filename="package://meshes/thigh.dae" scale="1 1 1"/>
      </geometry>
      <material name="orange"/>
    </visual>
    <collision>
      <origin rpy="0 1.57079632679 0" xyz="0 0 -0.1"/>
      <geometry>
        <box size="0.2 0.0245 0.034"/>
      </geometry>
    </collision>
    <inertial>
      <origin rpy="0 0 0" xyz="-0.003237 -0.022327 -0.027326"/>
      <mass value="1.013"/>
      <inertia ixx="0.005529065" ixy="4.825e-06" ixz="0.000343869" iyy="0.005139339" iyz="2.2448e-05" izz="0.001367788"/>
    </inertial>
  </link>
  <joint name="HL_KFE" type="revolute">
    <origin rpy="0 0 0" xyz="0 0 -0.2"/>
    <parent link="HL_UPPER_LEG"/>
    <child link="HL_LOWER_LEG"/>
    <axis xyz="0 1 0"/>
    <dynamics damping="0.01" friction="0.2"/>
    <limit effort="33.5" lower="-2.69653369433" upper="-0.916297857297" velocity="21"/>
  </joint>
  <link name="HL_LOWER_LEG">
    <visual>
      <origin rpy="0 0 0" xyz="0 0 0"/>
      <geometry>
        <mesh filename="package://meshes/calf.dae" scale="1 1 1"/>
      </geometry>
      <material name="orange"/>
    </visual>
    <collision>
      <origin rpy="0 1.57079632679 0" xyz="0 0 -0.1"/>
      <geometry>
        <box size="0.2 0.016 0.016"/>
      </geometry>
    </collision>
    <inertial>
      <origin rpy="0 0 0" xyz="0.006435 0.0 -0.107388"/>
      <mass value="0.166"/>
      <inertia ixx="0.002997972" ixy="0.0" ixz="-0.000141163" iyy="0.003014022" iyz="0.0" izz="3.2426e-05"/>
    </inertial>
  </link>
  <joint name="HL_ANKLE" type="fixed">
    <origin rpy="0 0 0" xyz="0 0 -0.2"/>
    <parent link="HL_LOWER_LEG"/>
    <child link="HL_FOOT"/>
  </joint>
  <link name="HL_FOOT">
    <visual>
      <origin rpy="0 0 0" xyz="0 0 0"/>
      <geometry>
        <sphere radius="0.01"/>
      </geometry>
      <material name="orange"/>
    </visual>
    <collision>
      <origin rpy="0 0 0" xyz="0 0 0"/>
      <geometry>
        <sphere radius="0.02"/>
      </geometry>
    </collision>
    <inertial>
      <mass value="0.06"/>
      <inertia ixx="9.6e-06" ixy="0.0" ixz="0.0" iyy="9.6e-06" iyz="0.0" izz="9.6e-06"/>
    </inertial>
  </link>

  <joint name="HR_HAA" type="revolute">
    <origin rpy="0 0 0" xyz="-0.1805 -0.047 0"/>
    <parent link="base_link"/>
    <child link="HR_SHOULDER"/>
    <axis xyz="1 0 0"/>
    <dynamics damping="0.01" friction="0.2"/>
    <limit effort="33.5" lower="-0.802851455917" upper="0.802851455917" velocity="21"/>
  </joint>
  <link name="HR_SHOULDER">
    <visual>
      <origin rpy="3.14159265359 3.14159265359 0" xyz="0 0 0"/>
      <geometry>
        <mesh filename="package://meshes/hip.dae" scale="1 1 1"/>
      </geometry>
      <material name="orange"/>
    </visual>
    <collision>
      <origin rpy="1.57079632679 0 0" xyz="0 0 0"/>
      <geometry>
        <cylinder length="0.04" radius="0.046"/>
      </geometry>
    </collision>
    <inertial>
      <origin rpy="0 0 0" xyz="0.003311 -0.000635 3.1e-05"/>
      <mass value="0.696"/>
      <inertia ixx="0.000469246" ixy="-9.409e-06" ixz="3.42e-07" iyy="0.00080749" iyz="4.66e-07" izz="0.000552929"/>
    </inertial>
  </link>
  <joint name="HR_HIP_FIXED" type="fixed">
    <origin rpy="0 0 0" xyz="0 -0.081 0"/>
    <parent link="HR_SHOULDER"/>
    <child link="HR_THIGH_COLLISION"/>
  </joint>
  <!-- this link is only for collision -->
  <link name="HR_THIGH_COLLISION">
    <collision>
      <origin rpy="1.57079632679 0 0" xyz="0 0 0"/>
      <geometry>
        <cylinder length="0.032" radius="0.041"/>
      </geometry>
    </collision>
  </link>
  <joint name="HR_HFE" type="revolute">
    <origin rpy="0 0 0" xyz="0 -0.0838 0"/>
    <parent link="HR_SHOULDER"/>
    <child link="HR_UPPER_LEG"/>
    <axis xyz="0 1 0"/>
    <dynamics damping="0.01" friction="0.2"/>
    <limit effort="33.5" lower="-1.0471975512" upper="4.18879020479" velocity="21"/>
  </joint>
  <link name="HR_UPPER_LEG">
    <visual>
      <origin rpy="0 0 0" xyz="0 0 0"/>
      <geometry>
        <mesh filename="package://meshes/thigh_mirror.dae" scale="1 1 1"/>
      </geometry>
      <material name="orange"/>
    </visual>
    <collision>
      <origin rpy="0 1.57079632679 0" xyz="0 0 -0.1"/>
      <geometry>
        <box size="0.2 0.0245 0.034"/>
      </geometry>
    </collision>
    <inertial>
      <origin rpy="0 0 0" xyz="-0.003237 0.022327 -0.027326"/>
      <mass value="1.013"/>
      <inertia ixx="0.005529065" ixy="-4.825e-06" ixz="0.000343869" iyy="0.005139339" iyz="-2.2448e-05" izz="0.001367788"/>
    </inertial>
  </link>
  <joint name="HR_KFE" type="revolute">
    <origin rpy="0 0 0" xyz="0 0 -0.2"/>
    <parent link="HR_UPPER_LEG"/>
    <child link="HR_LOWER_LEG"/>
    <axis xyz="0 1 0"/>
    <dynamics damping="0.01" friction="0.2"/>
    <limit effort="33.5" lower="-2.69653369433" upper="-0.916297857297" velocity="21"/>
  </joint>
  <link name="HR_LOWER_LEG">
    <visual>
      <origin rpy="0 0 0" xyz="0 0 0"/>
      <geometry>
        <mesh filename="package://meshes/calf.dae" scale="1 1 1"/>
      </geometry>
      <material name="orange"/>
    </visual>
    <collision>
      <origin rpy="0 1.57079632679 0" xyz="0 0 -0.1"/>
      <geometry>
        <box size="0.2 0.016 0.016"/>
      </geometry>
    </collision>
    <inertial>
      <origin rpy="0 0 0" xyz="0.006435 0.0 -0.107388"/>
      <mass value="0.166"/>
      <inertia ixx="0.002997972" ixy="0.0" ixz="-0.000141163" iyy="0.003014022" iyz="0.0" izz="3.2426e-05"/>
    </inertial>
  </link>
  <joint name="HR_ANKLE" type="fixed">
    <origin rpy="0 0 0" xyz="0 0 -0.2"/>
    <parent link="HR_LOWER_LEG"/>
    <child link="HR_FOOT"/>
  </joint>
  <link name="HR_FOOT">
    <visual>
      <origin rpy="0 0 0" xyz="0 0 0"/>
      <geometry>
        <sphere radius="0.01"/>
      </geometry>
      <material name="orange"/>
    </visual>
    <collision>
      <origin rpy="0 0 0" xyz="0 0 0"/>
      <geometry>
        <sphere radius="0.02"/>
      </geometry>
    </collision>
    <inertial>
      <mass value="0.06"/>
      <inertia ixx="9.6e-06" ixy="0.0" ixz="0.0" iyy="9.6e-06" iyz="0.0" izz="9.6e-06"/>
    </inertial>
  </link>

  <!-- <xacro:stairs stairs="15" xpos="0" ypos="2.0" zpos="0" /> -->
</robot>

